Workbook

Sheet Instructions
A1: SCALAPAY — Request for Proposal — Core Banking Platform: Payment Accounts
A3: Purpose & how responses are assessed
A4: Scalapay is selecting a core banking platform to launch and operate payment accounts and integrate them with our BNPL products. The evaluation is evidence-based: answers must be supported by artefacts — documentation, sandbox access, sample contracts, named references — rather than statements of capability. Scored questions use the 0–5 rubric below; a claim with no supporting artefact scores a maximum of 2. Nine pass/fail gates (G1–G9) are mandatory: each is defined on the Gates tab and flagged on the section tab where it applies. Failing any gate ends the evaluation before commercial review, regardless of scores elsewhere.
A6: How to complete this workbook
A7: • Tabs 1–9 — answer every question in the pink columns: Provider Response, Availability (where applicable) and Artefact Reference. “See attached” without a page or section reference is treated as unanswered.
A8: • Classify every functional capability as: available today (in production with live clients) / roadmap with a committable date / roadmap without a committable date / not available.
A9: • Gates tab — confirm each of the nine pass/fail gates. Any qualification must be stated in full; the gate definitions state which qualifications constitute failure.
A10: • Capability Matrix tab — complete one row per capability: availability, live production client count, integration mechanism, and whether Scalapay-side development is required.
A11: • All responses, technical documentation and support channels must be available in English. Identify any artefact that exists in Italian only.
A12: • Identify every subcontracted or third-party component (fraud engines, AML screening, card processors and the like) and the contractual relationship for each.
A13: • Grey columns are for Scalapay evaluators only — leave them empty.
A14: • Do not add, delete, reorder or renumber rows; the Scoring tab computes from these ranges.
A16: Evaluation process & timeline
A17: Milestone | B17: Owner | C17: Date | D17: Requirement
A18: RFP issued | B18: Scalapay | C18: [ ] | D18: Distribution to shortlisted providers
A19: Clarification questions close | B19: Provider | C19: [ ] | D19: Written questions; answers circulated to all providers
A20: Written response due | B20: Provider | C20: [ ] | D20: All tabs completed; artefacts attached
A21: Sandbox evaluation window | B21: Scalapay Engineering | C21: [ ] | D21: Minimum 10 business days of full sandbox access
A22: Technical deep-dive sessions | B22: Both | C22: [ ] | D22: Provider engineering, not sales, in attendance
A23: Reference calls | B23: Scalapay | C23: [ ] | D23: Two live-client references of comparable scale
A24: Scoring & decision | B24: Scalapay | C24: [ ] | D24: Weighted matrix — see Scoring tab
A26: Who does what
A27: The vendor completes every PINK cell: question responses, availability classifications and artefact references on tabs 1–9; gate confirmations and qualifications on the Gates tab; all capability details on the Capability Matrix; and the timeline dates if not pre-filled. Scalapay completes every GREY cell after the response is returned: scores (0–5) and evaluator notes on tabs 1–9, the Pass/Fail result for each gate, and matrix evaluator notes. The Scoring tab is entirely formula-driven from Scalapay’s blue-cell entries — neither party types into it. Vendors must leave all grey cells and the Scoring tab untouched; entries found there will be disregarded.
B28: PINK — vendor fills these cells
B29: GREY — Scalapay evaluation only; vendors leave empty
A31: Worked example (format only)
A32: Ref | B32: Q2.4
A33: Provider Response | B33: Yes — all mutating endpoints accept an Idempotency-Key header; replays return the original response. Keys retained 30 days.
A34: Availability | B34: Available today
A35: Artefact Reference | B35: API Reference v4.2, §3.1, pp. 41–43; sandbox demo
A37: Scoring rubric (Scalapay use)
A38: 0 | B38: No answer, fundamentally non-compliant, or the evidence contradicts the claim
A39: 1 | B39: Material gap; unsupported statement of future intention
A40: 2 | B40: Partial capability, or a claim supported only by weak evidence
A41: 3 | B41: Meets the requirement with acceptable evidence and manageable qualifications
A42: 4 | B42: Fully meets the requirement with strong production evidence
A43: 5 | B43: Exceeds the requirement, proven at comparable scale, with contractual commitment

Sheet 1. Functional Scope
A1: Section 1 — Functional Scope
A2: Every capability in 1.1–1.4 is required unless marked otherwise. Capabilities listed at 1.6 are out of scope. For every capability, complete the Capability Matrix tab: availability, number of live production clients using it today, integration mechanism (API / webhook / batch / BPO / manual), and any Scalapay-side development required. The questions at the bottom of this tab apply to the section as a whole.
A4: 1.1 Payment account core
A5: • | B5: Account opening and closing via API, including KYC data handoff and status callbacks
A6: • | B6: IBAN real-time issuance and lifecycle: allocation of Italian IBANs, reservation, and treatment on account closure
A7: • | B7: Balance model: available, current and ledger balances exposed via API, with defined semantics for how holds, reservations and pending postings affect each
A8: • | B8: Statements, customer transaction history and fee postings: periodic statements (PDF and CAMT), full history via API, and itemised fee posting
A9: • | B9: Account debit instructions via API
A10: • | B10: Fee manager, configurable at account and product level
A11: • | B11: Intra-institution transfers: account-to-account transactions within Scalapay IP. A transfer from account 1 to account 2, which is not recorded under the SEPA scheme.
A12: • | B12: Credit transfers: standard SCT and SCT Inst: send and receive, scheduled and recurring SCT. R-transaction and exception handling.
A13: • | B13: Verification of Payee (VOP) compliance, including the applicable EU deadlines
A14: • | B14: Account blocks, freezes (full, debit-only, credit-only), holds and reserved balances, all controllable via API with reason codes
A15: • | B15: Payment limits: per-transaction and per-period limits, configurable at account and product level
A16: • | B16: Beneficiary management: trusted beneficiary lists, per-transaction and per-period limits, configurable at account and product level
... A24: • | B24: Cash deposits: at ATMs and affiliated POS (feature subject to a monthly limit).
A25: 1.2 Risk, compliance & reconciliation
A26: • | B26: Compliant digital preservation (It. conservazione a norma), aligned with the eIDAS qualified electronic archiving service
A27: • | B27: Fraud management: real-time transaction screening, rules engine, case management
A28: • | B28: AML: customer screening, ongoing monitoring, suspicious activity workflow (transaction monitoring)
A29: • | B29: Daily account reconciliation, platform-native or delivered as BPO (state which, with staffing and cut-off times)
A30: • | B30: Regulatory reporting for Italian payment institutions, including threshold-driven reporting for movements above €5,000 (SARA, tax monitoring / Anagrafe dei rapporti, CRS/FATCA)
A31: • | B31: Accounting and general ledger outputs, with export formats and posting frequency
A32: • | B32: Customer complaints and payment investigations: intake, tracking, case management, and support for regulatory response deadlines
A33: 1.3 Cards
A34: • | B34: Connection of debit and credit cards to the payment account: card payments and withdrawals
A35: 1.4 Credit integration
A36: • | B36: Credit on payment orders: The customer submits a payment order via the services offered by the Institution, which simultaneously provides a credit facility for the same amount - available for SCT-SCT Inst-Recurrent SCT-Domestic Payment-card payment
A37: • | B37: Credit on incoming payments: customer express the preference in advance to pay a future payment in instalments and/or defer it, subject to predefined conditions - available for SDD (Core)-MIT and recurrent card payment
A38: Scalapay will connect payment accounts to credit facilities — automatic instalment debit, fund disbursement, bullet financing, flexible repayment plans. Respond to both architectures:
A39: • | B39: Option A — integration with Scalapay’s existing BNPL systems, adapted to new financing types. Describe the integration points, events and constraints your platform imposes.
A40: • | B40: Option B — a credit management system integrated with the account platform (e.g. Qinetic or equivalent). Describe what is native, what is partnered, and the maturity of each.
A41: 1.5 Product configurability & extensibility
A42: Our roadmap includes financing types that do not exist today, and successors to those. The determining factor is not whether your platform supports them now, but who changes the platform when we need them — and how fast. We will evaluate every provider against the standard that the client can configure or build new account and credit products without a vendor change request.
A43: 1.6 Out of scope
A44: Multi-currency accounts and FX are out of scope: Scalapay operates in euro markets only. Providers may note multi-currency capability for information; it will not be scored and must not be priced into the proposal.
A45: 1.7 Custodian and correspondant bank integration
A46: Please list existing integration with custodian banks and correspondant bank for the services in scope.
A48: Questions
A49: WHO DOES WHAT Vendor: fill Provider Response, Availability and Artefact Reference (PINK). Scalapay: fills Score and Evaluator Notes (GREY). Vendors must leave grey cells empty.
...

Sheet 2. API & Integration
A1: Section 2 — API & Integration Quality
A2: Answers in this section must be verifiable against the artefacts requested in Sections 3 and 7 (specifications, developer portal access, sandbox behaviour).
A4: WHO DOES WHAT Vendor: fill Provider Response, Availability and Artefact Reference (PINK). Scalapay: fills Score and Evaluator Notes (GREY). Vendors must leave grey cells empty.
A5: Ref | B5: Question | C5: Provider Response | D5: Availability | E5: Artefact Reference | F5: Score (0–5) | G5: Evaluator Notes
A6: Q2.1 | B6: Provide the complete OpenAPI (or equivalent machine-readable) specification for all in-scope APIs with your response. State the specification version and how it is kept in sync with production behaviour.
A7: Q2.2 | B7: Describe your API versioning policy: how breaking changes are introduced, the contractually committed minimum deprecation notice, and how many versions are supported concurrently.
A8: Q2.3 | B8: Which events are delivered by webhook and which require polling? Provide the full event catalogue, delivery guarantees (at-least-once / at-most-once), retry and backoff behaviour, and the signature verification scheme. State which operations are asynchronous and the guaranteed maximum completion time for each.
A9: Q2.4 | B9: Do all mutating endpoints support idempotency keys? Describe replay behaviour and key retention period.
A10: Q2.5 | B10: State rate limits per endpoint category, burst allowances, the response returned when limited, and the process for negotiating higher limits.
A11: Q2.6 | B11: Provide your error taxonomy. Are errors machine-parseable with stable codes, and is there a documented mapping from error code to recommended client behaviour?
A12: Q2.7 | B12: Give measured production p50/p95/p99 latency — not targets — for account opening, debit instruction and transfer instruction.
A13: Q2.8 | B13: Describe authentication and authorisation: mTLS/OAuth2 details, key rotation, and per-environment credential isolation.
A14: Q2.9 | B14: Describe any batch interfaces that remain mandatory: file formats, delivery windows, and the roadmap for replacing them with APIs.
A15: Q2.10 | B15: State the sustained and peak throughput (requests and events per second) your platform supports per endpoint category in production today, the maximum capacity you have actually load-tested, and scaling behaviour beyond it — horizontal auto-scaling, pre-provisioning, or throttling. Describe the process and lead time for a planned capacity increase, for example ahead of Black Friday peaks.
A16: Q2.11 | B16: For events: what ordering guarantees apply — global, per-account, or none? Can Scalapay replay events on demand over a chosen time range, and what is the replay retention window? Describe dead-letter handling when our endpoint is unavailable: queue retention, alerting to Scalapay, and the recovery procedure.
A17: Q2.12 | B17: Do all API responses and events carry a correlation or trace identifier, propagated end-to-end across your internal services, that Scalapay can log, quote in support tickets, and reconcile against our own tracing? State the identifier scheme and its retention in your logs.
... A20: Q2.15 | B20: Describe bulk interfaces for initial migration and ongoing imports: account and balance migration, supported formats, throughput, validation and error reporting, dry-run support, and whether bulk operations can be exercised in sandbox.

Sheet 3. Sandbox & DX
A1: Section 3 — Sandbox & Developer Experience
A2: Scalapay will run a hands-on sandbox evaluation before any commercial decision. The sandbox must represent production behaviour closely enough that integration estimates derived from it are reliable.
A3: PASS/FAIL GATE G1 — Pre-contract sandbox access. Criterion: Working sandbox credentials for up to ten named Scalapay engineers, issued within five business days of the written response, at no cost, for a minimum of ten consecutive business days before contract signature. The sandbox must expose every in-scope flow: account opening, debit and transfer instructions, instant payments, card flows, VOP, and failure simulation. Confirm on the Gates tab; full definition (evidence, qualifications, test point) is there.
A5: WHO DOES WHAT Vendor: fill Provider Response, Availability and Artefact Reference (PINK). Scalapay: fills Score and Evaluator Notes (GREY). Vendors must leave grey cells empty.
A6: Ref | B6: Question | C6: Provider Response | D6: Availability | E6: Artefact Reference | F6: Score (0–5) | G6: Evaluator Notes
A7: Q3.1 | B7: Confirm sandbox access for up to ten named Scalapay engineers within five business days of your response, for a minimum ten-business-day window.
A8: Q3.2 | B8: Describe sandbox fidelity relative to production: which services are fully simulated, which are stubbed, which are absent. Cover instant payments, card flows, VOP and failure scenarios explicitly.
A9: Q3.3 | B9: How is test data provisioned? Can Scalapay create test accounts, simulate insufficient-funds failures, trigger webhook events and reset state on demand without raising tickets?
A10: Q3.4 | B10: State the sandbox availability commitment, its maintenance windows, and whether sandbox incidents carry any SLA. Is the sandbox updated in lockstep with production releases, and what notice is given before sandbox-visible changes?
A11: Q3.5 | B11: Based on your three most recent client onboardings, what is the expected time from credential issuance to first successful API call? We will measure this ourselves during evaluation.
A12: Q3.6 | B12: Describe developer tooling: Postman/Bruno collections, SDKs and their languages, CLI tools, mock servers and local testing options.
A13: Q3.7 | B13: Is performance and load testing supported — in the sandbox or in a dedicated performance environment? State the throughput limits, whether tests can be run at agreed production-like volumes before go-live, and any associated cost.
A14: Q3.8 | B14: List every environment provided (sandbox, UAT, performance, production), how configuration is promoted between them — exportable configuration-as-code, manual re-entry, or vendor ticket — and how configuration drift between environments is detected.

Sheet 4. Documentation
A1: Section 4 — Integration Documentation Quality
A2: Documentation is evaluated as a deliverable in its own right. We are asking for the documentation itself, not a description of it. Documentation that cannot support unassisted integration work is a defect, and is treated as one under Section 5.
A3: PASS/FAIL GATE G2 — 48-hour unassisted documentation exercise. Criterion: Unconditional written consent for Scalapay engineers to spend 48 hours with your documentation and sandbox, unassisted, attempting the account-opening and debit-instruction flows end to end. Confirm on the Gates tab; full definition (evidence, qualifications, test point) is there.
A4: PASS/FAIL GATE G3 — English-language documentation and support. Criterion: All technical documentation required for the in-scope integration, and every support channel including P1 on-call, is available in English. Italian-only artefacts are acceptable only where an English version is contractually committed before integration start. Confirm on the Gates tab; full definition (evidence, qualifications, test point) is there.
A6: WHO DOES WHAT Vendor: fill Provider Response, Availability and Artefact Reference (PINK). Scalapay: fills Score and Evaluator Notes (GREY). Vendors must leave grey cells empty.
A7: Ref | B7: Question | C7: Provider Response | D7: Availability | E7: Artefact Reference | F7: Score (0–5) | G7: Evaluator Notes
A8: Q4.1 | B8: Provide evaluation access to your full developer portal with this response. Identify any documentation that exists in Italian only, and state whether English versions are committed and by when.
A9: Q4.2 | B9: Provide the complete API reference for account opening and debit instruction, with request and response examples for success and for each failure mode.
A10: Q4.3 | B10: Provide sequence diagrams for the in-scope end-to-end flows: account opening with KYC callbacks, scheduled instalment debit (success and failure), instant payment send and receive, and card authorisation against the account.
A11: Q4.4 | B11: Provide your error-handling and reconciliation guides, including how a client is expected to detect and repair state divergence.
A12: Q4.5 | B12: Provide the documentation changelog for the last twelve months, plus two examples of updates issued in response to client-reported gaps in the last six months. We will use these to assess whether documentation is actively maintained.
A13: Q4.6 | B13: Who owns documentation internally — a dedicated team, the engineering teams, or nobody in particular? How do clients report documentation defects, and what is the committed turnaround?

Sheet 5. Build-Phase Support
A1: Section 5 — Build-Phase Support Commitments
A2: Steady-state SLAs (Section 6) do not cover the period that most determines whether this project succeeds: the implementation. The commitments below must be contractual, not described as typical engagement practice.
A3: PASS/FAIL GATE G4 — Build-phase commitments are contractual. Criterion: Every commitment listed at 5.1 is accepted as a contractual obligation, individually and without dilution. Confirm on the Gates tab; full definition (evidence, qualifications, test point) is there.
A5: 5.1 Required commitments
A6: • | B6: Named technical integration lead: a single accountable engineer-level contact — not an account manager or a ticket queue — with committed weekly availability, named in the contract, and a defined substitution process.
A7: • | B7: Build-blocker response SLA: a first technical response, not an acknowledgement, within 4 business hours for issues blocking integration progress, with a defined path to resolution.
A8: • | B8: Direct engineering channel: a shared Slack or Teams channel with your integration engineers for the duration of the build. Email-only or portal-only support is not acceptable during the build.
A9: • | B9: Weekly joint working sessions: standing technical sessions with your engineers present, minuted, with tracked actions.
A10: • | B10: Sandbox defect turnaround: committed fix or workaround timelines by severity for defects found in sandbox during the build.
A11: • | B11: Documentation defects are defects: gaps or errors found during the build enter the same workflow, with the same turnaround commitments, as software defects.
A12: • | B12: Executive escalation: any build-blocker unresolved after 5 business days escalates automatically to your CTO or Head of Engineering, with a joint remediation plan within 2 further business days.
A14: Questions
A15: WHO DOES WHAT Vendor: fill Provider Response, Availability and Artefact Reference (PINK). Scalapay: fills Score and Evaluator Notes (GREY). Vendors must leave grey cells empty.
A16: Ref | B16: Question | C16: Provider Response | D16: Availability | E16: Artefact Reference | F16: Score (0–5) | G16: Evaluator Notes
A17: Q5.1 | B17: Confirm each commitment in 5.1 individually, stating any you will not contractually commit to and why.
A18: Q5.2 | B18: Name the proposed integration lead (or the role profile, if not yet assignable), their engineering background, and the percentage of their time dedicated to Scalapay during the build.
A19: Q5.3 | B19: How many concurrent client implementations is your integration team running today, and what is its headcount? How is capacity contention between clients resolved?
A20: Q5.4 | B20: Provide your implementation methodology and a reference project plan from a comparable client: phases, durations, Scalapay-side effort assumptions, and the three risks that most commonly cause slippage. State planned versus actual durations for your last three onboardings of comparable scope.
A21: Q5.5 | B21: Describe handover from implementation to steady-state support: what knowledge transfer occurs, and does the named integration lead remain reachable post-go-live?
A22: Q5.6 | B22: What penalties or remediation apply if build-phase commitments are missed — response times, defect turnaround, or milestone dates attributable to you?
A23: Q5.7 | B23: If any part of the implementation is delivered by a system integrator or partner rather than your own team, identify them and state which single party is contractually accountable to Scalapay for delivery, defects and the commitments in 5.1. Shared or ambiguous accountability will be scored down.

Sheet 6. SLAs & Support
A1: Section 6 — Steady-State SLAs & Support
A2: PASS/FAIL GATE G4 — Build-phase commitments are contractual. Criterion: Every commitment listed at 5.1 is accepted as a contractual obligation, individually and without dilution. Confirm on the Gates tab; full definition (evidence, qualifications, test point) is there.
A4: WHO DOES WHAT Vendor: fill Provider Response, Availability and Artefact Reference (PINK). Scalapay: fills Score and Evaluator Notes (GREY). Vendors must leave grey cells empty.
A5: Ref | B5: Question | C5: Provider Response | D5: Availability | E5: Artefact Reference | F5: Score (0–5) | G5: Evaluator Notes
A6: Q6.1 | B6: State the contractual uptime commitment per service tier (core account APIs, instant payments, card authorisation, webhooks, reporting), the measurement method and exclusions. Provide actual measured uptime for each over the last 12 months.
A7: Q6.2 | B7: Provide incident severity definitions (P1–P4) with the contractually committed response time, update cadence and target resolution for each, plus the escalation path with named roles at each level and the criteria that trigger automatic escalation.
A8: Q6.3 | B8: State support hours and languages. Confirm 24/7 coverage for P1 incidents affecting payment processing, with English-speaking engineers on call.
A9: Q6.4 | B9: Detail the service credit and penalty regime for SLA breaches, including caps, and whether repeated breach is a termination trigger.
A10: Q6.5 | B10: Commit to a written post-incident review within 5 business days of every P1 and P2, including root cause and remediation. Provide two recent redacted examples.
A11: Q6.6 | B11: How is planned maintenance scheduled and communicated, and what is the maximum monthly planned downtime for payment-critical services?
A12: Q6.7 | B12: Provide your incident history for the last 12 months: the number of P1 and P2 incidents, and the three most impactful, with root causes.
A13: Q6.8 | B13: What client-accessible operational telemetry do you provide: a status page with per-component granularity, API and webhook-delivery metrics (success rates, latency, queue depth) via dashboard or metrics API, and proactive alerting to Scalapay when our integration degrades? State the retention period for operational metrics.
A14: Q6.9 | B14: State your production release frequency and the change-notification process: channel, notice period by change type (functional, non-functional, breaking), and whether Scalapay can schedule or defer adoption of changes affecting our integration.

Sheet 7. Resilience & Data
A1: Section 7 — Resilience, Security, Compliance & Data
A2: 7.1 covers operational resilience, security and compliance (Q7.1–Q7.8). 7.2 covers data ownership and accessibility (Q7.9–Q7.14): all account, transaction, customer and operational data generated on the platform under this engagement is Scalapay’s data, and answers in 7.2 will be verified during the sandbox evaluation.
A3: PASS/FAIL GATE G6 — EU data residency. Criterion: All personal and transactional data is stored and processed within the EU/EEA, by the provider and by every subprocessor. Confirm on the Gates tab; full definition (evidence, qualifications, test point) is there.
A4: PASS/FAIL GATE G7 — EBA / DORA outsourcing compliance. Criterion: Compliance with the EBA Guidelines on outsourcing arrangements and with DORA, with contractual audit and access rights for Scalapay and for Banca d’Italia. Confirm on the Gates tab; full definition (evidence, qualifications, test point) is there.
A5: PASS/FAIL GATE G8 — Exit and migration terms. Criterion: The contract commits to full data export in machine-readable formats, defined migration assistance with stated duration and pricing, and a stated maximum notice period. Confirm on the Gates tab; full definition (evidence, qualifications, test point) is there.
A6: PASS/FAIL GATE G9 — Data ownership and unrestricted access. Criterion: The contract states that Scalapay owns all account, transaction, customer and operational data generated under the engagement, and can access and export it in full, in machine-readable formats, without restriction, additional licensing, tickets or per-extract fees. Confirm on the Gates tab; full definition (evidence, qualifications, test point) is there.
A8: WHO DOES WHAT Vendor: fill Provider Response, Availability and Artefact Reference (PINK). Scalapay: fills Score and Evaluator Notes (GREY). Vendors must leave grey cells empty.
A9: Ref | B9: Question | C9: Provider Response | D9: Availability | E9: Artefact Reference | F9: Score (0–5) | G9: Evaluator Notes
A10: Q7.1 | B10: Describe your disaster recovery architecture: contractually committed RTO and RPO per service tier, last full DR test date and results. Confirm Scalapay’s right to participate in an annual DR test.
A11: Q7.2 | B11: Where is data hosted and processed, including all subprocessors? Confirm EU data residency for all personal and transactional data, and describe the subprocessor change-notification process.
A12: Q7.3 | B12: Confirm compliance with the EBA Guidelines on outsourcing arrangements and with DORA, including audit and access rights for Scalapay and for Banca d’Italia. Provide your standard outsourcing register pack.
A13: Q7.4 | B13: Provide current certifications and attestations (ISO 27001, SOC 2 Type II, PCI DSS where card data is in scope) with scope statements and dates.
A14: Q7.5 | B14: Describe your secure development lifecycle, vulnerability management SLAs by severity, and client notification commitments for vulnerabilities affecting our services. State penetration testing cadence, whether client-commissioned tests are permitted, and how findings are communicated.
A15: Q7.6 | B15: Detail exit and migration terms: data export formats and completeness, committed assistance, transition service duration and pricing, and the contractual maximum notice period. Exit terms are weighted heavily — describe a past client offboarding and how it was executed.
A16: Q7.7 | B16: What are your business continuity arrangements for BPO-delivered services, including key-person risk?
A17: Q7.8 | B17: State the deployment models available (managed SaaS in dedicated tenancy, shared SaaS, self-hosted in Scalapay’s cloud account) and for each: who operates the infrastructure, upgrade cadence and control, and cost implications.
A18: Q7.9 | B18: Confirm data ownership as stated above, and identify any category you consider excluded — derived scores, model outputs, platform telemetry — with justification.
A19: Q7.10 | B19: Describe Scalapay’s access to our own raw platform data for analytics: is there a structured data layer or near-real-time streaming export we can connect to our own warehouse and BI tooling, independent of your reporting modules? State formats, latency and any charges.
A20: Q7.11 | B20: Can Scalapay run ad-hoc queries against our own data self-service, or are non-standard extracts fulfilled by your team on request? If the latter: turnaround, cost, and the roadmap to self-service.
A21: Q7.12 | B21: State data retention and queryability windows: how far back data is available online via API or data layer, what is archived, and the lead time and cost to retrieve archived data.
... A23: Q7.14 | B23: For BPO-delivered services, what working data does Scalapay see: the full underlying records and break-level detail, or only outcome summaries?

Sheet 8. Delivery & References
A1: Section 8 — Delivery, Team & References
A2: This section is unweighted in the scoring model; reference calls and the sandbox evaluation may adjust category scores by ±1 point where evidence contradicts the written response.
A4: WHO DOES WHAT Vendor: fill Provider Response, Availability and Artefact Reference (PINK). Scalapay: fills Score and Evaluator Notes (GREY). Vendors must leave grey cells empty.
A5: Ref | B5: Question | C5: Provider Response | D5: Availability | E5: Artefact Reference | F5: Score (0–5) | G5: Evaluator Notes
A6: Q8.1 | B6: Provide the proposed delivery team structure with named individuals or role profiles, their fintech and payments experience, and location and time zone.
A7: Q8.2 | B7: Provide the committed timeline for the feasibility analysis, GAP analysis and economic impact assessment, and the remedies if those dates slip for reasons attributable to you.
A8: Q8.3 | B8: Provide two references from live clients of comparable scale running the in-scope capabilities in production, with consent for direct calls including their engineering leads.
A9: Q8.4 | B9: Describe your product roadmap for the next 18 months for the in-scope services, and how client input is weighted in prioritisation.
A10: Q8.5 | B10: State your financial standing (audited accounts or equivalent assurance), ownership structure, and any pending material litigation or regulatory matters.

Sheet 9. Commercials
A1: Section 9 — Commercials
A2: All pricing in EUR, exclusive of VAT, and valid for at least 6 months from submission.
A4: WHO DOES WHAT Vendor: fill Provider Response, Availability and Artefact Reference (PINK). Scalapay: fills Score and Evaluator Notes (GREY). Vendors must leave grey cells empty.
A5: Ref | B5: Question | C5: Provider Response | D5: Availability | E5: Artefact Reference | F5: Score (0–5) | G5: Evaluator Notes
A6: Q9.1 | B6: Provide pricing broken out per service — account maintenance, transactions by type, instant payments, cards, fraud, AML, reconciliation BPO, reporting — not as a single bundled figure. Include all one-off implementation costs.
A7: Q9.2 | B7: State how the pricing model behaves at 2x, 5x and 10x current projected volumes, including volume discounts and any minimum commitments.
A8: Q9.3 | B8: Identify every cost that is usage-triggered or open-ended: per-ticket support charges, change-request day rates, per-report fees and the like.
A9: Q9.4 | B9: State price review mechanics: indexation, caps on annual increases, and notice periods.
A10: Q9.5 | B10: Confirm that sandbox access, documentation access and all evaluation activities in this RFP are provided at no cost.

Sheet Gates
A1: WHO DOES WHAT — Vendor: confirm each gate and state any qualifications (PINK). Scalapay: decides Pass/Fail and records evaluator notes (GREY) — the vendor confirmation is input to that decision, not the decision itself. Vendors must leave grey cells empty.
A2: ID | B2: Gate | C2: Applies to | D2: Acceptance Criterion | E2: Required Evidence | F2: Qualifications & Carve-outs | G2: Tested | H2: Provider Confirmation | I2: Provider Qualifications / Evidence Reference | J2: Scalapay Result | K2: Evaluator Notes
A3: G1 | B3: Pre-contract sandbox access | C3: Tab 3 | D3: Working sandbox credentials for up to ten named Scalapay engineers, issued within five business days of the written response, at no cost, for a minimum of ten consecutive business days before contract signature. The sandbox must expose every in-scope flow: account opening, debit and transfer instructions, instant payments, card flows, VOP, and failure simulation. | E3: Credentials issued on time; the fidelity statement at Q3.2 verified hands-on by Scalapay engineers during the window. | F3: Fail if access is conditional on contract signature or payment, if any in-scope flow is absent from the sandbox, or if state reset and failure simulation require provider tickets. Standard confidentiality and fair-use terms are acceptable. | G3: At credential issuance, then throughout the sandbox evaluation window.
A4: G2 | B4: 48-hour unassisted documentation exercise | C4: Tab 4 | D4: Unconditional written consent for Scalapay engineers to spend 48 hours with your documentation and sandbox, unassisted, attempting the account-opening and debit-instruction flows end to end. | E4: Explicit confirmation in the written response; developer portal access provided with the response (Q4.1). | F4: Fail if consent is refused, or made conditional on provider supervision, mandatory briefings, or restrictions on which documentation may be used. Confidentiality terms are acceptable. The outcome of the exercise is scored under Section 10, not gated — only refusal fails. | G4: Written response; the exercise itself runs during the sandbox window.
A5: G3 | B5: English-language documentation and support | C5: Tab 4 | D5: All technical documentation required for the in-scope integration, and every support channel including P1 on-call, is available in English. Italian-only artefacts are acceptable only where an English version is contractually committed before integration start. | E5: Developer portal inspection; the Italian-only artefact list with committed dates (Q4.1); the support model at Q6.3. | F5: Fail if any artefact required for integration, or any support tier, is Italian-only with no committed English date. | G5: Written response; verified during the 48-hour exercise and the sandbox window.
A6: G4 | B6: Build-phase commitments are contractual | C6: Tab 5 | D6: Every commitment listed at 5.1 is accepted as a contractual obligation, individually and without dilution. | E6: Item-by-item confirmation at Q5.1, plus the corresponding contract schedule or marked-up terms. | F6: Fail if any 5.1 item is refused or restated as ‘typical practice’, ‘best efforts’ or equivalent non-binding language. An explicit substitute commitment of equal or greater strength is acceptable. | G6: Written response; confirmed at contract mark-up before award.
A7: G5 | B7: SLAs carry financial remedies | C7: Tab 6 | D7: Every uptime and P1/P2 incident SLA carries a defined, automatic financial remedy — service credits or penalties — with the calculation stated in the contract. | E7: The SLA schedule and the credit/penalty regime (Q6.1, Q6.4). | F7: Fail if remedies are discretionary, framed as goodwill, or require case-by-case negotiation. Remedy caps are acceptable if stated; measurement exclusions must be listed exhaustively. | G7: Written response; confirmed at contract mark-up.
A8: G6 | B8: EU data residency | C8: Tab 7 | D8: All personal and transactional data is stored and processed within the EU/EEA, by the provider and by every subprocessor. | E8: Hosting architecture and the complete subprocessor list with processing locations (Q7.2); data processing terms. | F8: Fail if any in-scope data is stored or processed outside the EU/EEA. Remote support access from outside the EU/EEA must be declared, with controls described; undeclared third-country access fails. | G8: Written response; verified against the outsourcing register pack.
A9: G7 | B9: EBA / DORA outsourcing compliance | C9: Tab 7 | D9: Compliance with the EBA Guidelines on outsourcing arrangements and with DORA, with contractual audit and access rights for Scalapay and for Banca d’Italia. | E9: The outsourcing register information pack (Q7.3) and the contract clauses granting audit and access rights. | F9: Fail if audit rights are limited to third-party reports only, or if regulator access rights are excluded or qualified. | G9: Written response; confirmed at contract mark-up.
A10: G8 | B10: Exit and migration terms | C10: Tab 7 | D10: The contract commits to full data export in machine-readable formats, defined migration assistance with stated duration and pricing, and a stated maximum notice period. | E10: The exit schedule or contract terms (Q7.6); the description of a past client offboarding. | F10: Fail if any exit element is deferred to ‘be agreed at the time of exit’ or priced on an uncommitted basis. | G10: Written response; confirmed at contract mark-up.
A11: G9 | B11: Data ownership and unrestricted access | C11: Tab 7 | D11: The contract states that Scalapay owns all account, transaction, customer and operational data generated under the engagement, and can access and export it in full, in machine-readable formats, without restriction, additional licensing, tickets or per-extract fees. | E11: The contract clause; self-service data access demonstrated during the sandbox evaluation (Q7.10, Q7.11). | F11: Exclusions limited to the provider’s proprietary model internals are acceptable if declared under Q7.9. Fail if access to Scalapay’s raw data is billable, ticketed, or contractually rate-limited. | G11: Written response; verified in sandbox; confirmed at contract mark-up.

Sheet Capability Matrix
A1: Capability Availability Matrix — one row per capability
A2: Availability: AT = available today (production, live clients) / RM = roadmap (committed date) / NA = not available. Integration: API / Webhook / Batch / BPO / Manual. Where a capability is delivered by a subcontractor or partner, name them in Provider Notes.
A3: WHO DOES WHAT — Vendor: complete Availability, Live Clients, Integration, Scalapay Dev Required and Provider Notes (PINK). Scalapay: records Evaluator Notes (GREY). Vendors must leave grey cells empty.
A5: Capability | B5: Requirement | C5: Availability | D5: Live Production Clients | E5: Integration Mechanism | F5: Scalapay Dev Required? | G5: Provider Notes | H5: Evaluator Notes
A6: Account opening & closing | B6: Required
A7: IBAN issuance & lifecycle | B7: Required
A8: Balance model (available / current / ledger) | B8: Required
A9: Account debit instructions | B9: Required
A10: Standard SCT (send & receive) | B10: Required
A11: Instant payments (SCT Inst) | B11: Required
A12: Verification of Payee (VOP) | B12: Required
A13: R-transactions: returns, recalls, rejects, investigations | B13: Required
A14: Blocks, freezes, holds & reserved balances | B14: Required
A15: Beneficiary management & payment limits | B15: Required
A16: Statements, transaction history & fee postings | B16: Required
A17: SEPA Direct Debit & mandate management | B17: Optional
... A29: Credit integration — Option B (integrated CMS) | B29: Required

Sheet Scoring
B2: Weighted Scoring Summary
B3: Computed automatically from the section tabs and the Gates tab. Do not overwrite formula cells.
B5: Category | C5: Weight | D5: Avg Score (0–5) | E5: Weighted Contribution | F5: Primary Evidence
B6: Functional coverage, maturity & configurability | C6: 0.2 | D6: =IFERROR(ROUND(AVERAGE('1. Functional Scope'!F51:F61),2),"—") -> — | E6: =IF(ISNUMBER(D6),D6/5*C6,0) -> 0 | F6: Capability Matrix; live client counts; configurability answers
B7: API & integration quality | C7: 0.15 | D7: =IFERROR(ROUND(AVERAGE('2. API & Integration'!F6:F20),2),"—") -> — | E7: =IF(ISNUMBER(D7),D7/5*C7,0) -> 0 | F7: Specifications; sandbox verification
B8: Build-phase support model | C8: 0.15 | D8: =IFERROR(ROUND(AVERAGE('5. Build-Phase Support'!F17:F23),2),"—") -> — | E8: =IF(ISNUMBER(D8),D8/5*C8,0) -> 0 | F8: Contractual commitments; references
B9: Sandbox & developer experience | C9: 0.1 | D9: =IFERROR(ROUND(AVERAGE('3. Sandbox & DX'!F7:F14),2),"—") -> — | E9: =IF(ISNUMBER(D9),D9/5*C9,0) -> 0 | F9: Measured time to first call
B10: Documentation quality | C10: 0.1 | D10: =IFERROR(ROUND(AVERAGE('4. Documentation'!F8:F13),2),"—") -> — | E10: =IF(ISNUMBER(D10),D10/5*C10,0) -> 0 | F10: 48-hour unassisted exercise
B11: Steady-state SLAs & support | C11: 0.1 | D11: =IFERROR(ROUND(AVERAGE('6. SLAs & Support'!F6:F14),2),"—") -> — | E11: =IF(ISNUMBER(D11),D11/5*C11,0) -> 0 | F11: SLA terms; 12-month incident history
B12: Resilience, security, compliance & data access | C12: 0.1 | D12: =IFERROR(ROUND(AVERAGE('7. Resilience & Data'!F10:F23),2),"—") -> — | E12: =IF(ISNUMBER(D12),D12/5*C12,0) -> 0 | F12: Certifications; DR evidence; exit terms; data access demo
B13: Commercials & TCO | C13: 0.1 | D13: =IFERROR(ROUND(AVERAGE('9. Commercials'!F6:F10),2),"—") -> — | E13: =IF(ISNUMBER(D13),D13/5*C13,0) -> 0 | F13: Per-service pricing; volume scenarios
B14: TOTAL | C14: =SUM(C6:C13) -> 1 | E14: =SUM(E6:E13) -> 0
B16: Pass/Fail Gate Status
B17: Gates passed | C17: =COUNTIF(Gates!$J$3:$J$11,"Pass") -> 0
B18: Gates failed | C18: =COUNTIF(Gates!$J$3:$J$11,"Fail") -> 0
B19: Gates pending | C19: =9-COUNTIF(Gates!$J$3:$J$11,"Pass")-COUNTIF(Gates!$J$3:$J$11,"Fail") -> 9
B20: Evaluation status | C20: =IF(COUNTIF(Gates!$J$3:$J$11,"Fail")>0,"ELIMINATED — gate failed",IF(COUNTIF(Gates!$J$3:$J$11,"Pass")=9,"All gates passed — score stands","Gates pending")) -> Gates pending
B22: Note: Tab 8 (Delivery, Team & References) is unweighted; reference calls and the sandbox evaluation may adjust category scores by ±1 point where evidence contradicts the written response.
